<?xml version="1.0" encoding="UTF-8"?>
<testng-results ignored="0" total="1" passed="1" failed="0" skipped="0">
  <reporter-output>
  </reporter-output>
  <suite started-at="2020-03-10T19:38:55 IST" name="Default suite" finished-at="2020-03-10T19:38:55 IST" duration-ms="79">
    <groups>
    </groups>
    <test started-at="2020-03-10T19:38:55 IST" name="Default test" finished-at="2020-03-10T19:38:55 IST" duration-ms="79">
      <class name="io.vlabs.testng.testdata.ExceptionTest">
        <test-method signature="exceptionTest()[pri:0, instance:io.vlabs.testng.testdata.ExceptionTest@7f1302d6]" started-at="2020-03-10T19:38:55 IST" name="exceptionTest" finished-at="2020-03-10T19:38:55 IST" duration-ms="20" status="PASS">
          <exception class="java.lang.NumberFormatException">
            <message>
              <![CDATA[For input string: "abcd"]]>
            </message>
            <full-stacktrace>
              <![CDATA[java.lang.NumberFormatException: For input string: "abcd"
at java.base/java.lang.NumberFormatException.forInputString(NumberFormatException.java:68)
at java.base/java.lang.Integer.parseInt(Integer.java:658)
at java.base/java.lang.Integer.parseInt(Integer.java:776)
at io.vlabs.testng.testdata.ExceptionTest.exceptionTest(ExceptionTest.java:11)
at java.base/jdk.internal.reflect.NativeMethodAccessorImpl.invoke0(Native Method)
at java.base/jdk.internal.reflect.NativeMethodAccessorImpl.invoke(NativeMethodAccessorImpl.java:62)
at java.base/jdk.internal.reflect.DelegatingMethodAccessorImpl.invoke(DelegatingMethodAccessorImpl.java:43)
at java.base/java.lang.reflect.Method.invoke(Method.java:567)
at org.testng.internal.MethodInvocationHelper.invokeMethod(MethodInvocationHelper.java:134)
at org.testng.internal.TestInvoker.invokeMethod(TestInvoker.java:597)
at org.testng.internal.TestInvoker.invokeTestMethod(TestInvoker.java:173)
at org.testng.internal.MethodRunner.runInSequence(MethodRunner.java:46)
at org.testng.internal.TestInvoker$MethodInvocationAgent.invoke(TestInvoker.java:816)
at org.testng.internal.TestInvoker.invokeTestMethods(TestInvoker.java:146)
at org.testng.internal.TestMethodWorker.invokeTestMethods(TestMethodWorker.java:146)
at org.testng.internal.TestMethodWorker.run(TestMethodWorker.java:128)
at java.base/java.util.ArrayList.forEach(ArrayList.java:1507)
at org.testng.TestRunner.privateRun(TestRunner.java:766)
at org.testng.TestRunner.run(TestRunner.java:587)
at org.testng.SuiteRunner.runTest(SuiteRunner.java:384)
at org.testng.SuiteRunner.runSequentially(SuiteRunner.java:378)
at org.testng.SuiteRunner.privateRun(SuiteRunner.java:337)
at org.testng.SuiteRunner.run(SuiteRunner.java:286)
at org.testng.SuiteRunnerWorker.runSuite(SuiteRunnerWorker.java:53)
at org.testng.SuiteRunnerWorker.run(SuiteRunnerWorker.java:96)
at org.testng.TestNG.runSuitesSequentially(TestNG.java:1187)
at org.testng.TestNG.runSuitesLocally(TestNG.java:1109)
at org.testng.TestNG.runSuites(TestNG.java:1039)
at org.testng.TestNG.run(TestNG.java:1007)
at org.testng.remote.AbstractRemoteTestNG.run(AbstractRemoteTestNG.java:115)
at org.testng.remote.RemoteTestNG.initAndRun(RemoteTestNG.java:251)
at org.testng.remote.RemoteTestNG.main(RemoteTestNG.java:77)
]]>
            </full-stacktrace>
          </exception> <!-- java.lang.NumberFormatException -->
          <reporter-output>
          </reporter-output>
        </test-method> <!-- exceptionTest -->
      </class> <!-- io.vlabs.testng.testdata.ExceptionTest -->
    </test> <!-- Default test -->
  </suite> <!-- Default suite -->
</testng-results>
